#VRML_SIM R2023b utf8

EXTERNPROTO "https://raw.githubusercontent.com/cyberbotics/webots/R2025a/projects/objects/backgrounds/protos/TexturedBackground.proto"
EXTERNPROTO "https://raw.githubusercontent.com/cyberbotics/webots/R2023b/projects/objects/floors/protos/RectangleArena.proto"
EXTERNPROTO "https://raw.githubusercontent.com/cyberbotics/webots/R2023b/projects/appearances/protos/BrushedAluminium.proto"
EXTERNPROTO "https://raw.githubusercontent.com/cyberbotics/webots/R2023b/projects/appearances/protos/Parquetry.proto"

WorldInfo {
}
Viewpoint {
  orientation 0.06963544379376047 -0.9253728474012909 -0.3726070292682 5.884588290210225
  position -1.5170515367699897 -0.4768812790004722 0.6535433131884649
}
TexturedBackground {
  texture "empty_office"
}
DirectionalLight {
  ambientIntensity 1
  direction 0.51 0.3 -1
  intensity 1.5
}
Solid {
  translation 0 -0.91 0
  children [
    Shape {
      appearance PBRAppearance {
        roughness 0.9
        metalness 0
      }
      geometry Plane {
        size 2 2
      }
    }
  ]
  name "rectangle arena"
  model "rectangle arena"
  boundingObject Plane {
    size 2 2
  }
}
DEF TARGET Solid {
  translation -0.00678015 -0.320677 0.00995086
  rotation 0.005603290572395506 0.9999843014441584 -2.5034820376214623e-16 -3.1415926535897913
  children [
    Shape {
      appearance Appearance {
        material Material {
          diffuseColor 0.8 0 0
        }
      }
      geometry Box {
        size 0.025 0.05 0.02
      }
    }
  ]
  name "box"
  boundingObject Box {
    size 0.025 0.05 0.02
  }
  physics Physics {
    density 10000
  }
}
Robot {
  children [
    Shape {
      appearance DEF three_d_printed PBRAppearance {
        baseColor 0 1 0
        roughness 0.8
      }
      geometry DEF Base Mesh {
        url [
          "../protos/assets/Base.stl"
        ]
      }
    }
    Shape {
      appearance DEF sts3215 PBRAppearance {
        baseColor 0.239216 0.239216 0.239216
        roughness 0.8
      }
      geometry DEF Base_Motor Mesh {
        url [
          "../protos/assets/Base_Motor.stl"
        ]
      }
    }
    HingeJoint {
      jointParameters HingeJointParameters {
        position 2.534826244038259e-07
        axis 0 6e-06 1
        anchor 0 -0.0452 0.0165
      }
      device [
        RotationalMotor {
          name "1"
          maxVelocity 1
          maxTorque 25
        }
        PositionSensor {
          name "sensor_1"
        }
      ]
      endPoint Solid {
        translation 0 -0.0452 0.0165
        rotation 0.9999999999999721 -1.6656685337745832e-07 -1.6656590827950446e-07 1.5707900000000234
        children [
          Shape {
            appearance USE three_d_printed
            geometry DEF Rotation_Pitch Mesh {
              url [
                "../protos/assets/Rotation_Pitch.stl"
              ]
            }
          }
          Shape {
            appearance USE sts3215
            geometry DEF Rotation_Pitch_Motor Mesh {
              url [
                "../protos/assets/Rotation_Pitch_Motor.stl"
              ]
            }
          }
          HingeJoint {
            jointParameters HingeJointParameters {
              position -3.9692065834423485e-08
              anchor 0 0.1025 0.0306
            }
            device [
              RotationalMotor {
                name "2"
                maxVelocity 1
                maxTorque 25
              }
              PositionSensor {
                name "sensor_2"
              }
            ]
            endPoint Solid {
              translation 0 0.1025 0.0306
              rotation -1 0 0 1.8000001854470407
              children [
                Shape {
                  appearance USE three_d_printed
                  geometry DEF Upper_Arm Mesh {
                    url [
                      "../protos/assets/Upper_Arm.stl"
                    ]
                  }
                }
                Shape {
                  appearance USE sts3215
                  geometry DEF Upper_Arm_Motor Mesh {
                    url [
                      "../protos/assets/Upper_Arm_Motor.stl"
                    ]
                  }
                }
                HingeJoint {
                  jointParameters HingeJointParameters {
                    position 4.719150126922143e-07
                    anchor 0 0.11257 0.028
                  }
                  device [
                    RotationalMotor {
                      name "3"
                      maxVelocity 1
                      maxTorque 25
                    }
                    PositionSensor {
                      name "sensor_3"
                    }
                  ]
                  endPoint Solid {
                    translation 0 0.11257 0.028
                    rotation 1 0 0 1.5707928647187366
                    children [
                      Shape {
                        appearance USE three_d_printed
                        geometry DEF Lower_Arm Mesh {
                          url [
                            "../protos/assets/Lower_Arm.stl"
                          ]
                        }
                      }
                      Shape {
                        appearance USE sts3215
                        geometry DEF Lower_Arm_Motor Mesh {
                          url [
                            "../protos/assets/Lower_Arm_Motor.stl"
                          ]
                        }
                      }
                      HingeJoint {
                        jointParameters HingeJointParameters {
                          position 1.099296330861175e-07
                          anchor 0 0.0052 0.1349
                        }
                        device [
                          RotationalMotor {
                            name "4"
                            maxVelocity 1
                            minPosition -2.5
                            maxPosition 1.2
                            maxTorque 25
                          }
                          PositionSensor {
                            name "sensor_4"
                          }
                        ]
                        endPoint Solid {
                          translation 0 0.0052 0.1349
                          rotation -1 0 0 0.9999992684089939
                          children [
                            Shape {
                              appearance USE three_d_printed
                              geometry DEF Wrist_Pitch_Roll Mesh {
                                url [
                                  "../protos/assets/Wrist_Pitch_Roll.stl"
                                ]
                              }
                            }
                            Shape {
                              appearance USE sts3215
                              geometry DEF Wrist_Pitch_Roll_Motor Mesh {
                                url [
                                  "../protos/assets/Wrist_Pitch_Roll_Motor.stl"
                                ]
                              }
                            }
                            HingeJoint {
                              jointParameters HingeJointParameters {
                                position -5.444926302231799e-08
                                axis 0 1 0
                                anchor 0 -0.0601 0
                              }
                              device [
                                RotationalMotor {
                                  name "5"
                                  maxVelocity 1
                                  minPosition -3.14158
                                  maxPosition 3.14158
                                  maxTorque 25
                                }
                                PositionSensor {
                                  name "sensor_5"
                                }
                              ]
                              endPoint Solid {
                                translation 1.622618686772487e-06 -0.0601023848973723 -5.438107659583077e-06
                                rotation 6.135392587224871e-08 0.9999999999999918 1.1379780076259911e-07 1.5707899159154688
                                children [
                                  Shape {
                                    appearance USE three_d_printed
                                    geometry DEF Fixed_Jaw Mesh {
                                      url [
                                        "../protos/assets/Fixed_Jaw.stl"
                                      ]
                                    }
                                  }
                                  Shape {
                                    appearance USE sts3215
                                    geometry DEF Fixed_Jaw_Motor Mesh {
                                      url [
                                        "../protos/assets/Fixed_Jaw_Motor.stl"
                                      ]
                                    }
                                  }
                                  DEF Camera_mount Pose {
                                    translation -0.008 -0.01 -0.081
                                    rotation 0 -1 0 1.5708
                                    children [
                                      Camera {
                                        translation 0.05 -0.02 0
                                        rotation 0.5757502509063606 -0.5802691822367363 -0.5760202468035063 2.0943603061004255
                                        name "gripper_camera"
                                        fieldOfView 1.0472
                                        width 224
                                        height 224
                                        far 1
                                      }
                                    ]
                                    translationStep 0.001
                                  }
                                  HingeJoint {
                                    jointParameters HingeJointParameters {
                                      position -5.426505295501678e-09
                                      axis 1.3e-05 0 -1
                                      anchor -0.0202 -0.0244 0
                                    }
                                    device [
                                      RotationalMotor {
                                        name "6"
                                        maxVelocity 1
                                        minPosition -0.2000000022050026
                                        maxPosition 2
                                        maxTorque 25
                                      }
                                      PositionSensor {
                                        name "sensor_6"
                                      }
                                    ]
                                    endPoint Solid {
                                      translation -0.020199700845134474 -0.02440010635573455 -1.7904016552279895e-12
                                      rotation -1.7233758945390598e-08 1 -2.39590365547727e-11 3.141579999865389
                                      children [
                                        Shape {
                                          appearance PBRAppearance {
                                            roughness 0.8
                                          }
                                          geometry DEF Moving_Jaw Mesh {
                                            url [
                                              "../protos/assets/Moving_Jaw.stl"
                                            ]
                                          }
                                        }
                                      ]
                                      name "jaw"
                                      boundingObject DEF MOVING_JAW_boundingObj Group {
                                        children [
                                          Pose {
                                            translation -0.01 -0.076 0
                                            children [
                                              Box {
                                                size 0.004 0.01 0.013
                                              }
                                            ]
                                            translationStep 0.001
                                          }
                                          Pose {
                                            translation -0.007 -0.041 0
                                            children [
                                              Box {
                                                size 0.004 0.04 0.015
                                              }
                                            ]
                                            translationStep 0.001
                                          }
                                          Pose {
                                            translation -0.008 -0.067 0.001
                                            children [
                                              Box {
                                                size 0.004 0.01 0.013
                                              }
                                            ]
                                            translationStep 0.001
                                          }
                                        ]
                                      }
                                      physics Physics {
                                        density -1
                                        mass 0.020244
                                        centerOfMass [
                                          -0.001617 -0.030347 0.00045
                                        ]
                                        inertiaMatrix [
                                          1.11265e-05 8.99651e-06 2.99548e-06
                                          0 0 0
                                        ]
                                      }
                                    }
                                  }
                                  DEF END_EFFECTOR Solid {
                                    name "END_EFFECTOR"
                                  }
                                ]
                                name "gripper"
                                boundingObject DEF FIXED_JAW_boundingObj Group {
                                  children [
                                    Pose {
                                      translation 0.0178 -0.077 0
                                      children [
                                        Box {
                                          size 0.012 0.02 0.018
                                        }
                                      ]
                                      translationStep 0.0001
                                    }
                                    Pose {
                                      translation 0.0197 -0.0565 0
                                      children [
                                        Box {
                                          size 0.013 0.02 0.018
                                        }
                                      ]
                                      translationStep 0.0001
                                    }
                                    Pose {
                                      translation 0.012 -0.0917 -0.0006
                                      children [
                                        Box {
                                          size 0.004 0.01 0.013
                                        }
                                      ]
                                      translationStep 0.0001
                                    }
                                    Pose {
                                      translation 0.0103 -0.1017 -0.0006
                                      children [
                                        Box {
                                          size 0.004 0.01 0.011
                                        }
                                      ]
                                      translationStep 0.0001
                                    }
                                    Pose {
                                      translation 0.0226 -0.0257 -0.0005
                                      children [
                                        Box {
                                          size 0.02 0.04 0.038
                                        }
                                      ]
                                      translationStep 0.0001
                                    }
                                    Pose {
                                      translation 0.0226 -0.0257 -0.0005
                                      children [
                                        Box {
                                          size 0.02 0.04 0.038
                                        }
                                      ]
                                      translationStep 0.0001
                                    }
                                  ]
                                }
                                physics Physics {
                                  density -1
                                  mass 0.092986
                                  centerOfMass [
                                    0.005524 -0.028017 0.000484
                                  ]
                                  inertiaMatrix [
                                    5.03136e-05 4.64098e-05 2.72961e-05
                                    0 0 0
                                  ]
                                }
                              }
                            }
                          ]
                          name "wrist"
                          boundingObject Mesh {
                            url [
                              "../protos/assets/simplified/Wrist_Pitch_Roll.stl"
                            ]
                          }
                          physics Physics {
                            density -1
                            mass 0.066132
                            centerOfMass [
                              -0.008527 -0.035228 -2.3e-05
                            ]
                            inertiaMatrix [
                              3.45403e-05 2.39041e-05 1.94704e-05
                              0 0 0
                            ]
                          }
                          linearVelocity 1.9773400271444796e-07 -3.0444993419059036e-08 -3.3554449175656346e-07
                          angularVelocity 2.210758013608233e-07 -6.777087975863674e-10 2.5374044299698624e-06
                        }
                      }
                    ]
                    name "lower_arm"
                    boundingObject Mesh {
                      url [
                        "../protos/assets/simplified/Lower_Arm.stl"
                      ]
                    }
                    physics Physics {
                      density -1
                      mass 0.147968
                      centerOfMass [
                        -0.003396 0.001378 0.076801
                      ]
                      inertiaMatrix [
                        0.000138803 0.000107748 4.84242e-05
                        0 0 0
                      ]
                    }
                    linearVelocity -2.77941932242138e-08 -1.4880926285961217e-08 -2.7720946518812845e-07
                    angularVelocity 3.0490576881390167e-07 -5.786404260894545e-10 2.5374072049667076e-06
                  }
                }
              ]
              name "upper_arm"
              boundingObject Mesh {
                url [
                  "../protos/assets/simplified/Upper_Arm.stl"
                ]
              }
              physics Physics {
                density -1
                mass 0.162409
                centerOfMass [
                  -1.7e-05 0.07018 0.003105
                ]
                inertiaMatrix [
                  0.000213312 0.000167164 7.01522e-05
                  0 0 0
                ]
              }
              linearVelocity -9.762885844063365e-08 1.4397618972924718e-09 -1.989174917119242e-07
              angularVelocity 1.3825316954999005e-07 -3.828918770714744e-10 2.5374145592519106e-06
            }
          }
        ]
        name "shoulder"
        boundingObject Mesh {
          url [
            "../protos/assets/simplified/Rotation_Pitch.stl"
          ]
        }
        physics Physics {
          density -1
          mass 0.119226
          centerOfMass [
            -9.1e-05 0.059097 0.031089
          ]
          inertiaMatrix [
            5.94278e-05 5.89975e-05 3.13712e-05
            0 0 0
          ]
        }
        linearVelocity 7.88458090411038e-08 -4.064642577219993e-10 -1.155888547703177e-07
        angularVelocity 3.022169225529417e-09 -1.86469505467817e-10 2.5374190293975968e-06
      }
    }
    Camera {
      translation 0.0200079 -0.4438 0.377465
      rotation 0.357406871539237 -0.3574078715388776 -0.8628556898685809 -1.7177653071795866
      name "up_camera"
      fieldOfView 1.2
      width 640
      height 480
      near 0.05
      far 3
    }
    Camera {
      translation -0.424186 -0.244225 0.219242
      rotation 0.24253302904418084 0.9639981154421553 0.10902001305552893 0.508949
      name "side_camera"
      fieldOfView 1.2
      width 640
      height 480
      near 0.05
      far 3
    }
  ]
  name "so100"
  boundingObject Mesh {
    url [
      "../protos/assets/simplified/Base.stl"
    ]
  }
  controller "so100_tele"
  supervisor TRUE
  selfCollision TRUE
}
RectangleArena {
  translation -0.17 -0.2 0.01
  name "rectangle arena(1)"
  floorSize 0.09 0.09
  floorTileSize 1 1
  floorAppearance Parquetry {
    type "light strip"
  }
  wallThickness 0.0025
  wallHeight 0.025
  wallAppearance BrushedAluminium {
    colorOverride 0.333333 0.333333 1
  }
}
